<?xml version="1.0" encoding="utf-8"?>
<!-- =================================================================================== -->
<!-- |    This document was autogenerated by xacro from my_robot_integration.urdf.xacro | -->
<!-- |    EDITING THIS FILE BY HAND IS NOT RECOMMENDED                                 | -->
<!-- =================================================================================== -->
<!-- Name your robot here -->
<robot name="refinebot">
  <link name="chassis">
    <inertial>
      <origin rpy="0 0 0" xyz="-0.00124672984735278 0.432910880678776 -0.00229434822216398"/>
      <mass value="45.4284133348976"/>
      <inertia ixx="0.978097941440082" ixy="-0.00277854939075679" ixz="0.0154723204316408" iyy="3.32179827412401" iyz="0.00784791220302939" izz="4.21932891898083"/>
    </inertial>
    <visual>
      <origin rpy="0 0 0" xyz="0 0 0"/>
      <geometry>
        <mesh filename="package://refinebot/meshes/chassis.STL"/>
      </geometry>
      <material name="">
        <color rgba="0.792156862745098 0.819607843137255 0.933333333333333 1"/>
      </material>
    </visual>
    <collision>
      <origin rpy="0 0 0" xyz="0 0 0"/>
      <geometry>
        <mesh filename="package://refinebot/meshes/chassis.STL"/>
      </geometry>
    </collision>
  </link>
  <link name="front_right">
    <inertial>
      <origin rpy="0 0 0" xyz="5.55111512312578E-17 5.55111512312578E-17 0.0602099562076604"/>
      <mass value="3.10819434753196"/>
      <inertia ixx="0.0147424171546651" ixy="8.67361737988404E-19" ixz="5.55653613398821E-19" iyy="0.0147424171546651" iyz="-5.6920614055489E-19" izz="0.0132164942122196"/>
    </inertial>
    <visual>
      <origin rpy="0 0 0" xyz="0 0 0"/>
      <geometry>
        <mesh filename="package://refinebot/meshes/front_right.STL"/>
      </geometry>
      <material name="">
        <color rgba="0.792156862745098 0.819607843137255 0.933333333333333 1"/>
      </material>
    </visual>
    <collision>
      <origin rpy="0 0 0" xyz="0 0 0"/>
      <geometry>
        <mesh filename="package://refinebot/meshes/front_right.STL"/>
      </geometry>
    </collision>
  </link>
  <joint name="first_joint" type="continuous">
    <origin rpy="0.0072906 0.0047961 2.5597" xyz="0.27216 -0.001427 0.090488"/>
    <parent link="chassis"/>
    <child link="front_right"/>
    <axis xyz="0 0 1"/>
  </joint>
  <link name="front_left">
    <inertial>
      <origin rpy="0 0 0" xyz="0 6.02382727032946E-16 -0.155657161176605"/>
      <mass value="3.10819434753196"/>
      <inertia ixx="0.0147424171546651" ixy="-4.88991683891151E-21" ixz="1.02128415536314E-18" iyy="0.0147424171546651" iyz="5.84791546784369E-18" izz="0.0132164942122196"/>
    </inertial>
    <visual>
      <origin rpy="0 0 0" xyz="0 0 0"/>
      <geometry>
        <mesh filename="package://refinebot/meshes/front_left.STL"/>
      </geometry>
      <material name="">
        <color rgba="0.792156862745098 0.819607843137255 0.933333333333333 1"/>
      </material>
    </visual>
    <collision>
      <origin rpy="0 0 0" xyz="0 0 0"/>
      <geometry>
        <mesh filename="package://refinebot/meshes/front_left.STL"/>
      </geometry>
    </collision>
  </link>
  <joint name="second_joint" type="continuous">
    <origin rpy="3.1329 0 0" xyz="0.27216 0.0026736 0.56037"/>
    <parent link="chassis"/>
    <child link="front_left"/>
    <axis xyz="0 0 1"/>
  </joint>
  <link name="rear_right">
    <inertial>
      <origin rpy="0 0 0" xyz="-1.38777878078145E-16 0 0.0602099562076604"/>
      <mass value="3.10819434753196"/>
      <inertia ixx="0.0147424171546651" ixy="3.03576608295941E-18" ixz="5.55653613398821E-19" iyy="0.0147424171546651" iyz="-5.01443504774546E-19" izz="0.0132164942122196"/>
    </inertial>
    <visual>
      <origin rpy="0 0 0" xyz="0 0 0"/>
      <geometry>
        <mesh filename="package://refinebot/meshes/rear_right.STL"/>
      </geometry>
      <material name="">
        <color rgba="0.792156862745098 0.819607843137255 0.933333333333333 1"/>
      </material>
    </visual>
    <collision>
      <origin rpy="0 0 0" xyz="0 0 0"/>
      <geometry>
        <mesh filename="package://refinebot/meshes/rear_right.STL"/>
      </geometry>
    </collision>
  </link>
  <joint name="third_joint" type="continuous">
    <origin rpy="0.0072906 0.0047961 2.5597" xyz="-0.23584 -0.001427 0.090488"/>
    <parent link="chassis"/>
    <child link="rear_right"/>
    <axis xyz="0 0 1"/>
  </joint>
  <link name="rear_left">
    <inertial>
      <origin rpy="0 0 0" xyz="2.77555756156289E-17 6.37077196552482E-16 -0.155657161176605"/>
      <mass value="3.10819434753196"/>
      <inertia ixx="0.0147424171546651" ixy="-4.88991683891151E-21" ixz="1.02128415536314E-18" iyy="0.0147424171546651" iyz="5.84791546784369E-18" izz="0.0132164942122196"/>
    </inertial>
    <visual>
      <origin rpy="0 0 0" xyz="0 0 0"/>
      <geometry>
        <mesh filename="package://refinebot/meshes/rear_left.STL"/>
      </geometry>
      <material name="">
        <color rgba="0.792156862745098 0.819607843137255 0.933333333333333 1"/>
      </material>
    </visual>
    <collision>
      <origin rpy="0 0 0" xyz="0 0 0"/>
      <geometry>
        <mesh filename="package://refinebot/meshes/rear_left.STL"/>
      </geometry>
    </collision>
  </link>
  <joint name="fourth_joint" type="continuous">
    <origin rpy="3.1329 0 0" xyz="-0.23584 0.0026736 0.56037"/>
    <parent link="chassis"/>
    <child link="rear_left"/>
    <axis xyz="0 0 1"/>
  </joint>
  <link name="dummy">
  </link>
  <joint name="dummy_joint" type="fixed">
    <parent link="dummy"/>
    <child link="chassis"/>
  </joint>
  <transmission name="right_trans">
    <type>transmission_interface/SimpleTransmission</type>
    <joint name="third_joint">
      <hardwareInterface>EffortJointInterface</hardwareInterface>
    </joint>
    <actuator name="right_motor">
      <mechanicalReduction>50</mechanicalReduction>
      <hardwareInterface>EffortJointInterface</hardwareInterface>
    </actuator>
  </transmission>
  <transmission name="left_trans">
    <type>transmission_interface/SimpleTransmission</type>
    <joint name="fourth_joint">
      <hardwareInterface>EffortJointInterface</hardwareInterface>
    </joint>
    <actuator name="left_motor">
      <mechanicalReduction>50</mechanicalReduction>
      <hardwareInterface>EffortJointInterface</hardwareInterface>
    </actuator>
  </transmission>
  <link name="base_laser">
    <inertial>
      <origin rpy="0 0 0" xyz="-0.00029774 0.0066667 0.00013047"/>
      <mass value="0.15717"/>
      <inertia ixx="6.7885E-05" ixy="-1.3987E-07" ixz="-8.1554E-07" iyy="0.00013173" iyz="-9.0932E-08" izz="7.1972E-05"/>
    </inertial>
    <visual>
      <origin rpy="0 0 0" xyz="0 0 0"/>
      <geometry>
        <mesh filename="package://refinebot/meshes/ydlidar.dae"/>
      </geometry>
      <material name="">
        <color rgba="0.64706 0.61961 0.58824 1"/>
      </material>
    </visual>
    <collision>
      <origin rpy="0 0 0" xyz="0 0 0"/>
      <geometry>
        <mesh filename="package://refinebot/meshes/ydlidar.dae"/>
      </geometry>
    </collision>
  </link>
  <link name="laser_frame">
    <inertial>
      <origin rpy="0 0 0" xyz="-0.00036659 0.00064155 -0.00027052"/>
      <mass value="0.25482"/>
      <inertia ixx="8.9194E-05" ixy="1.8116E-07" ixz="3.6435E-08" iyy="0.00018279" iyz="2.423E-07" izz="0.00011103"/>
    </inertial>
    <!--visual>
      <origin
        xyz="0 0 0"
        rpy="0 0 0" />
      <geometry>
        <mesh
          filename="package://refinebot/meshes/ydlidar.dae" />
      </geometry>
      <material
        name="">
        <color
          rgba="0.64706 0.61961 0.58824 1" />
      </material>
    </visual-->
    <!--collision>
      <origin
        xyz="0 0 0"
        rpy="0 0 0" />
      <geometry>
        <mesh
          filename="package://refinebot/meshes/ydlidar.dae" />
      </geometry>
    </collision-->
  </link>
  <joint name="laser_joint" type="fixed">
    <origin rpy="0 0 0" xyz="0 0 0.03172"/>
    <parent link="base_laser"/>
    <child link="laser_frame"/>
    <axis xyz="0 0 0"/>
  </joint>
  <!-- Add your gazebo sensors here -->
  <gazebo reference="base_laser">
    <!-- <gravity>true</gravity> -->
    <!-- Gazebo has fixed set of Sensors types. Check them out here <> -->
    <sensor name="laser" type="ray">
      <!-- Add in your sensor characteristics -->
      <pose> 0 0 0 0 0 0 </pose>
      <visualise>true</visualise>
      <update_rate>40</update_rate>
      <!-- <always_on>true</always_on> -->
      <ray>
        <scan>
          <horizontal>
            <samples>720</samples>
            <resolution>1</resolution>
            <min_angle>-1.570796</min_angle>
            <max_angle>1.570796</max_angle>
          </horizontal>
        </scan>
        <range>
          <min>0.10</min>
          <max>30.0</max>
          <resolution>0.01</resolution>
        </range>
        <noise>
          <type>gaussian</type>
          <mean>0.0</mean>
          <stddev>0.01</stddev>
        </noise>
      </ray>
      <plugin filename="libgazebo_ros_laser.so" name="gazebo_ros_head_hokuyo_controller">
        <!-- Use topic name as /my_robot/scan -->
        <topicName>/refinebot/scan</topicName>
        <frameName>laser_frame</frameName>
      </plugin>
    </sensor>
  </gazebo>
  <!--  Gazebo plugin for control here is already added for you -->
  <gazebo>
    <plugin filename="libgazebo_ros_control.so" name="gazebo_ros_control">
      <robotNamespace>/refinebot</robotNamespace>
    </plugin>
  </gazebo>
  <!-- Create a joint between your robot and sensor -->
  <joint name="sensor_joint" type="fixed">
    <parent link="dummy"/>
    <child link="base_laser"/>
    <origin rpy="0 0 0" xyz="19 10 0"/>
  </joint>
</robot>
