<?xml version="1.0" encoding="utf-8"?>
<!-- This URDF was automatically created by SolidWorks to URDF Exporter! Originally created by Stephen Brawner (brawner@gmail.com) 
     Commit Version: 1.6.0-1-g15f4949  Build Version: 1.6.7594.29634
     For more information, please see http://wiki.ros.org/sw_urdf_exporter -->
<robot
  name="refinebot">
  <link
    name="chassis">
    <inertial>
      <origin
        xyz="-0.00124672984735278 0.432910880678776 -0.00229434822216398"
        rpy="0 0 0" />
      <mass
        value="45.4284133348976" />
      <inertia
        ixx="0.978097941440082"
        ixy="-0.00277854939075679"
        ixz="0.0154723204316408"
        iyy="3.32179827412401"
        iyz="0.00784791220302939"
        izz="4.21932891898083" />
    </inertial>
    <visual>
      <origin
        xyz="0 0 0"
        rpy="0 0 0" />
      <geometry>
        <mesh
          filename="package://refinebot/meshes/chassis.STL" />
      </geometry>
      <material
        name="">
        <color
          rgba="0.792156862745098 0.819607843137255 0.933333333333333 1" />
      </material>
    </visual>
    <collision>
      <origin
        xyz="0 0 0"
        rpy="0 0 0" />
      <geometry>
        <mesh
          filename="package://refinebot/meshes/chassis.STL" />
      </geometry>
    </collision>
  </link>
  <link
    name="front_right">
    <inertial>
      <origin
        xyz="5.55111512312578E-17 5.55111512312578E-17 0.0602099562076604"
        rpy="0 0 0" />
      <mass
        value="3.10819434753196" />
      <inertia
        ixx="0.0147424171546651"
        ixy="8.67361737988404E-19"
        ixz="5.55653613398821E-19"
        iyy="0.0147424171546651"
        iyz="-5.6920614055489E-19"
        izz="0.0132164942122196" />
    </inertial>
    <visual>
      <origin
        xyz="0 0 0"
        rpy="0 0 0" />
      <geometry>
        <mesh
          filename="package://refinebot/meshes/front_right.STL" />
      </geometry>
      <material
        name="">
        <color
          rgba="0.792156862745098 0.819607843137255 0.933333333333333 1" />
      </material>
    </visual>
    <collision>
      <origin
        xyz="0 0 0"
        rpy="0 0 0" />
      <geometry>
        <mesh
          filename="package://refinebot/meshes/front_right.STL" />
      </geometry>
    </collision>
  </link>
  <joint
    name="first_joint"
    type="continuous">
    <origin
      xyz="0.27216 -0.001427 0.090488"
      rpy="0.0072906 0.0047961 2.5597" />
    <parent
      link="chassis" />
    <child
      link="front_right" />
    <axis
      xyz="0 0 1" />
  </joint>
  <link
    name="front_left">
    <inertial>
      <origin
        xyz="0 6.02382727032946E-16 -0.155657161176605"
        rpy="0 0 0" />
      <mass
        value="3.10819434753196" />
      <inertia
        ixx="0.0147424171546651"
        ixy="-4.88991683891151E-21"
        ixz="1.02128415536314E-18"
        iyy="0.0147424171546651"
        iyz="5.84791546784369E-18"
        izz="0.0132164942122196" />
    </inertial>
    <visual>
      <origin
        xyz="0 0 0"
        rpy="0 0 0" />
      <geometry>
        <mesh
          filename="package://refinebot/meshes/front_left.STL" />
      </geometry>
      <material
        name="">
        <color
          rgba="0.792156862745098 0.819607843137255 0.933333333333333 1" />
      </material>
    </visual>
    <collision>
      <origin
        xyz="0 0 0"
        rpy="0 0 0" />
      <geometry>
        <mesh
          filename="package://refinebot/meshes/front_left.STL" />
      </geometry>
    </collision>
  </link>
  <joint
    name="second_joint"
    type="continuous">
    <origin
      xyz="0.27216 0.0026736 0.56037"
      rpy="3.1329 0 0" />
    <parent
      link="chassis" />
    <child
      link="front_left" />
    <axis
      xyz="0 0 1" />
  </joint>
  <link
    name="rear_right">
    <inertial>
      <origin
        xyz="-1.38777878078145E-16 0 0.0602099562076604"
        rpy="0 0 0" />
      <mass
        value="3.10819434753196" />
      <inertia
        ixx="0.0147424171546651"
        ixy="3.03576608295941E-18"
        ixz="5.55653613398821E-19"
        iyy="0.0147424171546651"
        iyz="-5.01443504774546E-19"
        izz="0.0132164942122196" />
    </inertial>
    <visual>
      <origin
        xyz="0 0 0"
        rpy="0 0 0" />
      <geometry>
        <mesh
          filename="package://refinebot/meshes/rear_right.STL" />
      </geometry>
      <material
        name="">
        <color
          rgba="0.792156862745098 0.819607843137255 0.933333333333333 1" />
      </material>
    </visual>
    <collision>
      <origin
        xyz="0 0 0"
        rpy="0 0 0" />
      <geometry>
        <mesh
          filename="package://refinebot/meshes/rear_right.STL" />
      </geometry>
    </collision>
  </link>
  <joint
    name="third_joint"
    type="continuous">
    <origin
      xyz="-0.23584 -0.001427 0.090488"
      rpy="0.0072906 0.0047961 2.5597" />
    <parent
      link="chassis" />
    <child
      link="rear_right" />
    <axis
      xyz="0 0 1" />
  </joint>
  <link
    name="rear_left">
    <inertial>
      <origin
        xyz="2.77555756156289E-17 6.37077196552482E-16 -0.155657161176605"
        rpy="0 0 0" />
      <mass
        value="3.10819434753196" />
      <inertia
        ixx="0.0147424171546651"
        ixy="-4.88991683891151E-21"
        ixz="1.02128415536314E-18"
        iyy="0.0147424171546651"
        iyz="5.84791546784369E-18"
        izz="0.0132164942122196" />
    </inertial>
    <visual>
      <origin
        xyz="0 0 0"
        rpy="0 0 0" />
      <geometry>
        <mesh
          filename="package://refinebot/meshes/rear_left.STL" />
      </geometry>
      <material
        name="">
        <color
          rgba="0.792156862745098 0.819607843137255 0.933333333333333 1" />
      </material>
    </visual>
    <collision>
      <origin
        xyz="0 0 0"
        rpy="0 0 0" />
      <geometry>
        <mesh
          filename="package://refinebot/meshes/rear_left.STL" />
      </geometry>
    </collision>
  </link>
  <joint
    name="fourth_joint"
    type="continuous">
    <origin
      xyz="-0.23584 0.0026736 0.56037"
      rpy="3.1329 0 0" />
    <parent
      link="chassis" />
    <child
      link="rear_left" />
    <axis
      xyz="0 0 1" />
  </joint>
  <link
    name="dummy">
  </link>
  <joint
    name="dummy_joint"
    type="fixed">
    <parent
    link="dummy" />
    <child
    link="chassis" />
  </joint>
  <transmission name="right_trans">
    <type>transmission_interface/SimpleTransmission</type>
    <joint name="third_joint">
      <hardwareInterface>VelocityJointInterface</hardwareInterface>
    </joint>
    <actuator name="right_motor">
      <mechanicalReduction>50</mechanicalReduction>
      <hardwareInterface>VelocityJointInterface</hardwareInterface>
    </actuator>
  </transmission>
  <transmission name="left_trans">
    <type>transmission_interface/SimpleTransmission</type>
    <joint name="fourth_joint">
      <hardwareInterface>VelocityJointInterface</hardwareInterface>
    </joint>
    <actuator name="left_motor">
      <mechanicalReduction>50</mechanicalReduction>
      <hardwareInterface>VelocityJointInterface</hardwareInterface>
    </actuator>
  </transmission>
</robot>
